Workbook

Sheet Dashboard
A1: Dormitory Event Attendance Manager
A3: Purpose
A4: This Manager tracks attendance at KUAS dormitory events. Student staff create new event sheets from the "Dorm Attendance" menu, enter attendee student ID numbers, and refresh the attendance log. Dorm tabs calculate each student's academic-year attendance and the dorm group score.
A7: Student Staff Workflow | E7: Quick Command Reference
A8: 1 | B8: Open this shared Google Sheet. | E8: Register a new student | F8: Students -> Register Student (Single) | G8: Adds one resident to the registry.
A9: 2 | B9: Dorm Attendance -> Events -> Create New Event Sheet (or Import Event to bulk-import an old paper list). | E9: Register many students at once | F9: Students -> Bulk Register (Paste from Excel) | G9: Paste ID / Dorm / Start Date / Notes rows.
A10: 3 | B10: Enter the event name and event date when prompted. | E10: A student moves to a different dorm | F10: Students -> Transfer Student (Change Dorm) | G10: Keeps their attendance history - does not reset it.
A11: 4 | B11: Enter attendee student ID numbers in Column A of the generated event tab, starting at row 8. | E11: A student moves out / leaves | F11: Students -> Deactivate Student (or Bulk Deactivate) | G11: Keeps history, hides them from active rosters.
A12: 5 | B12: Dorm Attendance -> Events -> Refresh Attendance Log. | E12: Check data for mistakes | F12: Maintenance -> Run Data Audit | G12: Lists duplicate IDs, unknown dorms, bad dates, etc.
A13: 6 | B13: Review dorm summaries on the relevant dorm tab. | E13: Start a new academic year | F13: Events -> Archive Previous Years’ Events | G13: Moves old logs out of the way and frees up Event IDs.
A15: Current Summary
A16: Current Academic Year Start | B16: =Settings!B3 -> 46266 | D16: Total Events This Year | E16: =COUNTIF(EventLog!C:C,">="&Settings!B3) -> 12 | G16: Total Attendance Records | H16: =MAX(0,COUNTA(AttendanceLog!A:A)-1) -> 372
A17: Total Active Students | B17: =COUNTIF(StudentRegistry!D:D,"Active") -> 238 | D17: Dorms Tracked | E17: =COUNTIF(Settings!B10:B1000,"Active") -> 5 | G17: Last Refreshed | H17: =Settings!B4 -> 46307.92
A20: Dorm | B20: Active Students | C20: Group Attendance Score | D20: Events Attended | F20: Eligible Event Slots
A21: Dorm A | B21: =COUNTIF('Dorm A'!B5:B1000,"Active") -> 64 | C21: ='Dorm A'!B2 -> 0.453125 | D21: =SUM('Dorm A'!E5:E1000) -> 87 | F21: =SUM('Dorm A'!F5:F1000) -> 192
A22: Dorm B | B22: =COUNTIF('Dorm B'!B5:B1000,"Active") -> 49 | C22: ='Dorm B'!B2 -> 0.37755102 | D22: =SUM('Dorm B'!E5:E1000) -> 74 | F22: =SUM('Dorm B'!F5:F1000) -> 196
A23: Dorm D | B23: =COUNTIF('Dorm D'!B5:B1000,"Active") -> 59 | C23: ='Dorm D'!B2 -> 0.48587571 | D23: =SUM('Dorm D'!E5:E1000) -> 86 | F23: =SUM('Dorm D'!F5:F1000) -> 177
A24: Dorm E | B24: =COUNTIF('Dorm E'!B5:B1000,"Active") -> 33 | C24: ='Dorm E'!B2 -> 0.68686869 | D24: =SUM('Dorm E'!E5:E1000) -> 68 | F24: =SUM('Dorm E'!F5:F1000) -> 99
A25: Meikokan | B25: =COUNTIF(Meikokan!B5:B1000,"Active") -> 33 | C25: =Meikokan!B2 -> 0.57575758 | D25: =SUM(Meikokan!E5:E1000) -> 57 | F25: =SUM(Meikokan!F5:F1000) -> 99

Sheet final
A1: final Attendance Summary (Inactive Dorm)
A2: Dorm Group Attendance Score | B2: =IFERROR(SUM(E5:E1000)/SUM(F5:F1000),0) -> 0 | D2: Academic Year Start | E2: =Settings!B3 -> 46266
A3: This dorm is inactive. Its sheet and historical attendance records are preserved, but it is not available for new student registrations.
A4: Student ID | B4: Status | C4: Dorm | D4: Start Date | E4: Events Attended | F4: Eligible Events | G4: Attendance % | H4: Last Attended

Sheet DeletedStudents
A1: Student ID | B1: Notes | C1: Dorm | D1: Status | E1: Start Date | F1: Attendance Records Archived | G1: Deleted At
A2: 2024M735 | B2: Mithun | C2: Dorm B | D2: Active | E2: 46263.333 | F2: 2 | G2: 46244.031
A3: 2022M933 | B3: 45901 | C3: Dorm D | D3: Inactive | E3: 45900.333 | F3: 0 | G3: 46244.517

Sheet BulkActionTemplates
A1: Bulk Action Templates
A2: Fill in a section below, select just the data rows (not the header or the italic example row), copy (Ctrl/Cmd+C), then open the matching dialog from the Dorm Attendance menu and paste (Ctrl/Cmd+V) into the box.
A4: 1. Bulk Register Students — Students -> Bulk Register (Paste from Excel)
A5: Student ID | B5: Dorm | C5: Start Date | D5: Notes
A6: 2024001 | B6: Dorm A | C6: 46113 | D6: Transfer student
A57: 3. Import Event — Events -> Import Event with Attendance Details
A58: Event Name | B58: Event Date | C58: Venue | D58: Attendee Count | E58: Expected Attendee Count
A59: Dorm D CCM | B59: 46304 | C59: Dorm D 1F | D59: 24 | E59: 24
A62: Attendee ID | B62: Attendee Dorm
A63: 2026m711 | B63: Dorm D
A64: 2026m639 | B64: Dorm D
A65: 2026m676 | B65: Dorm D
A66: 2026M613 | B66: Dorm D
A67: 2026b621 | B67: Dorm D
A68: 2026m810 | B68: Dorm D
A69: 2026B639 | B69: Dorm D
A70: 2026m725 | B70: Dorm D
A71: 2025B624 | B71: Dorm D
A72: 2026M713 | B72: Dorm D
A73: 2026m621 | B73: Dorm D
... A86: 2026b708 | B86: Dorm D

Sheet TransferLog
A1: Student ID | B1: From Dorm | C1: To Dorm | D1: Transferred At
A2: 2024M735 | B2: Dorm D | C2: Dorm B | D2: 46243.523
A3: 2025M740 | B3: Meikokan | C3: Dorm D | D3: 46244.516

Sheet Dorm A
A1: Dorm A Attendance Summary
A2: Dorm Group Attendance Score | B2: =IFERROR(SUM(E5:E1000)/SUM(F5:F1000),0) -> 0.453125 | D2: Academic Year Start | E2: =Settings!B3 -> 46266
A4: Student ID | B4: Status | C4: Dorm | D4: Start Date | E4: Events Attended | F4: Eligible Events | G4: Attendance % | H4: Last Attended
A5: 2023M002 | B5: Active | C5: Dorm A | D5: 46265.333 | E5: =IF($A5="","",SUMPRODUCT((AttendanceLog!$E$2:$E$5000=$A5)*(AttendanceLog!$C$2:$C$5000>=MAX($D5,Settings!$B$3))*((AttendanceLog!$I$2:$I$5000="")+(IFERROR(SEARCH(","&$C5&",",","&AttendanceLog!$I$2:$I$5000&","),0)>0)))) -> 2 | F5: =IF($A5="","",SUMPRODUCT((EventLog!$C$2:$C$5000>=MAX($D5,Settings!$B$3))*(EventLog!$C$2:$C$5000<=TODAY())*((EventLog!$F$2:$F$5000="")+(IFERROR(SEARCH(","&$C5&",",","&EventLog!$F$2:$F$5000&","),0)>0)))) -> 3 | G5: =IFERROR(E5/F5,0) -> 0.66666667 | H5: =IFERROR(__xludf.DUMMYFUNCTION("IFERROR(MAX(FILTER(AttendanceLog!$C:$C,AttendanceLog!$E:$E=$A5,(AttendanceLog!$I:$I="""")+(IFERROR(SEARCH("",""&$C5&"","","",""&AttendanceLog!$I:$I&"",""),0)>0))),"""")"),46289.33333333333) -> 46289.333
A6: 2023M629 | B6: Active | C6: Dorm A | D6: 46265.333 | E6: =IF($A6="","",SUMPRODUCT((AttendanceLog!$E$2:$E$5000=$A6)*(AttendanceLog!$C$2:$C$5000>=MAX($D6,Settings!$B$3))*((AttendanceLog!$I$2:$I$5000="")+(IFERROR(SEARCH(","&$C6&",",","&AttendanceLog!$I$2:$I$5000&","),0)>0)))) -> 2 | F6: =IF($A6="","",SUMPRODUCT((EventLog!$C$2:$C$5000>=MAX($D6,Settings!$B$3))*(EventLog!$C$2:$C$5000<=TODAY())*((EventLog!$F$2:$F$5000="")+(IFERROR(SEARCH(","&$C6&",",","&EventLog!$F$2:$F$5000&","),0)>0)))) -> 3 | G6: =IFERROR(E6/F6,0) -> 0.66666667 | H6: =IFERROR(__xludf.DUMMYFUNCTION("IFERROR(MAX(FILTER(AttendanceLog!$C:$C,AttendanceLog!$E:$E=$A6,(AttendanceLog!$I:$I="""")+(IFERROR(SEARCH("",""&$C6&"","","",""&AttendanceLog!$I:$I&"",""),0)>0))),"""")"),46289.33333333333) -> 46289.333
A7: 2024M674 | B7: Active | C7: Dorm A | D7: 46265.333 | E7: =IF($A7="","",SUMPRODUCT((AttendanceLog!$E$2:$E$5000=$A7)*(AttendanceLog!$C$2:$C$5000>=MAX($D7,Settings!$B$3))*((AttendanceLog!$I$2:$I$5000="")+(IFERROR(SEARCH(","&$C7&",",","&AttendanceLog!$I$2:$I$5000&","),0)>0)))) -> 2 | F7: =IF($A7="","",SUMPRODUCT((EventLog!$C$2:$C$5000>=MAX($D7,Settings!$B$3))*(EventLog!$C$2:$C$5000<=TODAY())*((EventLog!$F$2:$F$5000="")+(IFERROR(SEARCH(","&$C7&",",","&EventLog!$F$2:$F$5000&","),0)>0)))) -> 3 | G7: =IFERROR(E7/F7,0) -> 0.66666667 | H7: =IFERROR(__xludf.DUMMYFUNCTION("IFERROR(MAX(FILTER(AttendanceLog!$C:$C,AttendanceLog!$E:$E=$A7,(AttendanceLog!$I:$I="""")+(IFERROR(SEARCH("",""&$C7&"","","",""&AttendanceLog!$I:$I&"",""),0)>0))),"""")"),46289.33333333333) -> 46289.333
A8: 2024M696 | B8: Active | C8: Dorm A | D8: 46265.333 | E8: =IF($A8="","",SUMPRODUCT((AttendanceLog!$E$2:$E$5000=$A8)*(AttendanceLog!$C$2:$C$5000>=MAX($D8,Settings!$B$3))*((AttendanceLog!$I$2:$I$5000="")+(IFERROR(SEARCH(","&$C8&",",","&AttendanceLog!$I$2:$I$5000&","),0)>0)))) -> 2 | F8: =IF($A8="","",SUMPRODUCT((EventLog!$C$2:$C$5000>=MAX($D8,Settings!$B$3))*(EventLog!$C$2:$C$5000<=TODAY())*((EventLog!$F$2:$F$5000="")+(IFERROR(SEARCH(","&$C8&",",","&EventLog!$F$2:$F$5000&","),0)>0)))) -> 3 | G8: =IFERROR(E8/F8,0) -> 0.66666667 | H8: =IFERROR(__xludf.DUMMYFUNCTION("IFERROR(MAX(FILTER(AttendanceLog!$C:$C,AttendanceLog!$E:$E=$A8,(AttendanceLog!$I:$I="""")+(IFERROR(SEARCH("",""&$C8&"","","",""&AttendanceLog!$I:$I&"",""),0)>0))),"""")"),46289.33333333333) -> 46289.333
A9: 2025B141 | B9: Active | C9: Dorm A | D9: 46265.333 | E9: =IF($A9="","",SUMPRODUCT((AttendanceLog!$E$2:$E$5000=$A9)*(AttendanceLog!$C$2:$C$5000>=MAX($D9,Settings!$B$3))*((AttendanceLog!$I$2:$I$5000="")+(IFERROR(SEARCH(","&$C9&",",","&AttendanceLog!$I$2:$I$5000&","),0)>0)))) -> 0 | F9: =IF($A9="","",SUMPRODUCT((EventLog!$C$2:$C$5000>=MAX($D9,Settings!$B$3))*(EventLog!$C$2:$C$5000<=TODAY())*((EventLog!$F$2:$F$5000="")+(IFERROR(SEARCH(","&$C9&",",","&EventLog!$F$2:$F$5000&","),0)>0)))) -> 3 | G9: =IFERROR(E9/F9,0) -> 0 | H9: =IFERROR(__xludf.DUMMYFUNCTION("IFERROR(MAX(FILTER(AttendanceLog!$C:$C,AttendanceLog!$E:$E=$A9,(AttendanceLog!$I:$I="""")+(IFERROR(SEARCH("",""&$C9&"","","",""&AttendanceLog!$I:$I&"",""),0)>0))),"""")"),"")
A10: 2025B611 | B10: Active | C10: Dorm A | D10: 46265.333 | E10: =IF($A10="","",SUMPRODUCT((AttendanceLog!$E$2:$E$5000=$A10)*(AttendanceLog!$C$2:$C$5000>=MAX($D10,Settings!$B$3))*((AttendanceLog!$I$2:$I$5000="")+(IFERROR(SEARCH(","&$C10&",",","&AttendanceLog!$I$2:$I$5000&","),0)>0)))) -> 2 | F10: =IF($A10="","",SUMPRODUCT((EventLog!$C$2:$C$5000>=MAX($D10,Settings!$B$3))*(EventLog!$C$2:$C$5000<=TODAY())*((EventLog!$F$2:$F$5000="")+(IFERROR(SEARCH(","&$C10&",",","&EventLog!$F$2:$F$5000&","),0)>0)))) -> 3 | G10: =IFERROR(E10/F10,0) -> 0.66666667 | H10: =IFERROR(__xludf.DUMMYFUNCTION("IFERROR(MAX(FILTER(AttendanceLog!$C:$C,AttendanceLog!$E:$E=$A10,(AttendanceLog!$I:$I="""")+(IFERROR(SEARCH("",""&$C10&"","","",""&AttendanceLog!$I:$I&"",""),0)>0))),"""")"),46289.33333333333) -> 46289.333
A11: 2025B630 | B11: Active | C11: Dorm A | D11: 46265.333 | E11: =IF($A11="","",SUMPRODUCT((AttendanceLog!$E$2:$E$5000=$A11)*(AttendanceLog!$C$2:$C$5000>=MAX($D11,Settings!$B$3))*((AttendanceLog!$I$2:$I$5000="")+(IFERROR(SEARCH(","&$C11&",",","&AttendanceLog!$I$2:$I$5000&","),0)>0)))) -> 0 | F11: =IF($A11="","",SUMPRODUCT((EventLog!$C$2:$C$5000>=MAX($D11,Settings!$B$3))*(EventLog!$C$2:$C$5000<=TODAY())*((EventLog!$F$2:$F$5000="")+(IFERROR(SEARCH(","&$C11&",",","&EventLog!$F$2:$F$5000&","),0)>0)))) -> 3 | G11: =IFERROR(E11/F11,0) -> 0 | H11: =IFERROR(__xludf.DUMMYFUNCTION("IFERROR(MAX(FILTER(AttendanceLog!$C:$C,AttendanceLog!$E:$E=$A11,(AttendanceLog!$I:$I="""")+(IFERROR(SEARCH("",""&$C11&"","","",""&AttendanceLog!$I:$I&"",""),0)>0))),"""")"),"")
A12: 2025M010 | B12: Active | C12: Dorm A | D12: 46265.333 | E12: =IF($A12="","",SUMPRODUCT((AttendanceLog!$E$2:$E$5000=$A12)*(AttendanceLog!$C$2:$C$5000>=MAX($D12,Settings!$B$3))*((AttendanceLog!$I$2:$I$5000="")+(IFERROR(SEARCH(","&$C12&",",","&AttendanceLog!$I$2:$I$5000&","),0)>0)))) -> 0 | F12: =IF($A12="","",SUMPRODUCT((EventLog!$C$2:$C$5000>=MAX($D12,Settings!$B$3))*(EventLog!$C$2:$C$5000<=TODAY())*((EventLog!$F$2:$F$5000="")+(IFERROR(SEARCH(","&$C12&",",","&EventLog!$F$2:$F$5000&","),0)>0)))) -> 3 | G12: =IFERROR(E12/F12,0) -> 0 | H12: =IFERROR(__xludf.DUMMYFUNCTION("IFERROR(MAX(FILTER(AttendanceLog!$C:$C,AttendanceLog!$E:$E=$A12,(AttendanceLog!$I:$I="""")+(IFERROR(SEARCH("",""&$C12&"","","",""&AttendanceLog!$I:$I&"",""),0)>0))),"""")"),"")
A13: 2025M685 | B13: Active | C13: Dorm A | D13: 46265.333 | E13: =IF($A13="","",SUMPRODUCT((AttendanceLog!$E$2:$E$5000=$A13)*(AttendanceLog!$C$2:$C$5000>=MAX($D13,Settings!$B$3))*((AttendanceLog!$I$2:$I$5000="")+(IFERROR(SEARCH(","&$C13&",",","&AttendanceLog!$I$2:$I$5000&","),0)>0)))) -> 0 | F13: =IF($A13="","",SUMPRODUCT((EventLog!$C$2:$C$5000>=MAX($D13,Settings!$B$3))*(EventLog!$C$2:$C$5000<=TODAY())*((EventLog!$F$2:$F$5000="")+(IFERROR(SEARCH(","&$C13&",",","&EventLog!$F$2:$F$5000&","),0)>0)))) -> 3 | G13: =IFERROR(E13/F13,0) -> 0 | H13: =IFERROR(__xludf.DUMMYFUNCTION("IFERROR(MAX(FILTER(AttendanceLog!$C:$C,AttendanceLog!$E:$E=$A13,(AttendanceLog!$I:$I="""")+(IFERROR(SEARCH("",""&$C13&"","","",""&AttendanceLog!$I:$I&"",""),0)>0))),"""")"),"")
A14: 2025M695 | B14: Active | C14: Dorm A | D14: 46265.333 | E14: =IF($A14="","",SUMPRODUCT((AttendanceLog!$E$2:$E$5000=$A14)*(AttendanceLog!$C$2:$C$5000>=MAX($D14,Settings!$B$3))*((AttendanceLog!$I$2:$I$5000="")+(IFERROR(SEARCH(","&$C14&",",","&AttendanceLog!$I$2:$I$5000&","),0)>0)))) -> 0 | F14: =IF($A14="","",SUMPRODUCT((EventLog!$C$2:$C$5000>=MAX($D14,Settings!$B$3))*(EventLog!$C$2:$C$5000<=TODAY())*((EventLog!$F$2:$F$5000="")+(IFERROR(SEARCH(","&$C14&",",","&EventLog!$F$2:$F$5000&","),0)>0)))) -> 3 | G14: =IFERROR(E14/F14,0) -> 0 | H14: =IFERROR(__xludf.DUMMYFUNCTION("IFERROR(MAX(FILTER(AttendanceLog!$C:$C,AttendanceLog!$E:$E=$A14,(AttendanceLog!$I:$I="""")+(IFERROR(SEARCH("",""&$C14&"","","",""&AttendanceLog!$I:$I&"",""),0)>0))),"""")"),"")
A15: 2025M696 | B15: Active | C15: Dorm A | D15: 46265.333 | E15: =IF($A15="","",SUMPRODUCT((AttendanceLog!$E$2:$E$5000=$A15)*(AttendanceLog!$C$2:$C$5000>=MAX($D15,Settings!$B$3))*((AttendanceLog!$I$2:$I$5000="")+(IFERROR(SEARCH(","&$C15&",",","&AttendanceLog!$I$2:$I$5000&","),0)>0)))) -> 0 | F15: =IF($A15="","",SUMPRODUCT((EventLog!$C$2:$C$5000>=MAX($D15,Settings!$B$3))*(EventLog!$C$2:$C$5000<=TODAY())*((EventLog!$F$2:$F$5000="")+(IFERROR(SEARCH(","&$C15&",",","&EventLog!$F$2:$F$5000&","),0)>0)))) -> 3 | G15: =IFERROR(E15/F15,0) -> 0 | H15: =IFERROR(__xludf.DUMMYFUNCTION("IFERROR(MAX(FILTER(AttendanceLog!$C:$C,AttendanceLog!$E:$E=$A15,(AttendanceLog!$I:$I="""")+(IFERROR(SEARCH("",""&$C15&"","","",""&AttendanceLog!$I:$I&"",""),0)>0))),"""")"),"")
A16: 2025M750 | B16: Active | C16: Dorm A | D16: 46265.333 | E16: =IF($A16="","",SUMPRODUCT((AttendanceLog!$E$2:$E$5000=$A16)*(AttendanceLog!$C$2:$C$5000>=MAX($D16,Settings!$B$3))*((AttendanceLog!$I$2:$I$5000="")+(IFERROR(SEARCH(","&$C16&",",","&AttendanceLog!$I$2:$I$5000&","),0)>0)))) -> 0 | F16: =IF($A16="","",SUMPRODUCT((EventLog!$C$2:$C$5000>=MAX($D16,Settings!$B$3))*(EventLog!$C$2:$C$5000<=TODAY())*((EventLog!$F$2:$F$5000="")+(IFERROR(SEARCH(","&$C16&",",","&EventLog!$F$2:$F$5000&","),0)>0)))) -> 3 | G16: =IFERROR(E16/F16,0) -> 0 | H16: =IFERROR(__xludf.DUMMYFUNCTION("IFERROR(MAX(FILTER(AttendanceLog!$C:$C,AttendanceLog!$E:$E=$A16,(AttendanceLog!$I:$I="""")+(IFERROR(SEARCH("",""&$C16&"","","",""&AttendanceLog!$I:$I&"",""),0)>0))),"""")"),"")
A17: 2025M755 | B17: Active | C17: Dorm A | D17: 46265.333 | E17: =IF($A17="","",SUMPRODUCT((AttendanceLog!$E$2:$E$5000=$A17)*(AttendanceLog!$C$2:$C$5000>=MAX($D17,Settings!$B$3))*((AttendanceLog!$I$2:$I$5000="")+(IFERROR(SEARCH(","&$C17&",",","&AttendanceLog!$I$2:$I$5000&","),0)>0)))) -> 0 | F17: =IF($A17="","",SUMPRODUCT((EventLog!$C$2:$C$5000>=MAX($D17,Settings!$B$3))*(EventLog!$C$2:$C$5000<=TODAY())*((EventLog!$F$2:$F$5000="")+(IFERROR(SEARCH(","&$C17&",",","&EventLog!$F$2:$F$5000&","),0)>0)))) -> 3 | G17: =IFERROR(E17/F17,0) -> 0 | H17: =IFERROR(__xludf.DUMMYFUNCTION("IFERROR(MAX(FILTER(AttendanceLog!$C:$C,AttendanceLog!$E:$E=$A17,(AttendanceLog!$I:$I="""")+(IFERROR(SEARCH("",""&$C17&"","","",""&AttendanceLog!$I:$I&"",""),0)>0))),"""")"),"")
A18: 2025M761 | B18: Active | C18: Dorm A | D18: 46265.333 | E18: =IF($A18="","",SUMPRODUCT((AttendanceLog!$E$2:$E$5000=$A18)*(AttendanceLog!$C$2:$C$5000>=MAX($D18,Settings!$B$3))*((AttendanceLog!$I$2:$I$5000="")+(IFERROR(SEARCH(","&$C18&",",","&AttendanceLog!$I$2:$I$5000&","),0)>0)))) -> 0 | F18: =IF($A18="","",SUMPRODUCT((EventLog!$C$2:$C$5000>=MAX($D18,Settings!$B$3))*(EventLog!$C$2:$C$5000<=TODAY())*((EventLog!$F$2:$F$5000="")+(IFERROR(SEARCH(","&$C18&",",","&EventLog!$F$2:$F$5000&","),0)>0)))) -> 3 | G18: =IFERROR(E18/F18,0) -> 0 | H18: =IFERROR(__xludf.DUMMYFUNCTION("IFERROR(MAX(FILTER(AttendanceLog!$C:$C,AttendanceLog!$E:$E=$A18,(AttendanceLog!$I:$I="""")+(IFERROR(SEARCH("",""&$C18&"","","",""&AttendanceLog!$I:$I&"",""),0)>0))),"""")"),"")
A19: 2025M773 | B19: Active | C19: Dorm A | D19: 46265.333 | E19: =IF($A19="","",SUMPRODUCT((AttendanceLog!$E$2:$E$5000=$A19)*(AttendanceLog!$C$2:$C$5000>=MAX($D19,Settings!$B$3))*((AttendanceLog!$I$2:$I$5000="")+(IFERROR(SEARCH(","&$C19&",",","&AttendanceLog!$I$2:$I$5000&","),0)>0)))) -> 0 | F19: =IF($A19="","",SUMPRODUCT((EventLog!$C$2:$C$5000>=MAX($D19,Settings!$B$3))*(EventLog!$C$2:$C$5000<=TODAY())*((EventLog!$F$2:$F$5000="")+(IFERROR(SEARCH(","&$C19&",",","&EventLog!$F$2:$F$5000&","),0)>0)))) -> 3 | G19: =IFERROR(E19/F19,0) -> 0 | H19: =IFERROR(__xludf.DUMMYFUNCTION("IFERROR(MAX(FILTER(AttendanceLog!$C:$C,AttendanceLog!$E:$E=$A19,(AttendanceLog!$I:$I="""")+(IFERROR(SEARCH("",""&$C19&"","","",""&AttendanceLog!$I:$I&"",""),0)>0))),"""")"),"")
A20: 2025MM33 | B20: Active | C20: Dorm A | D20: 46265.333 | E20: =IF($A20="","",SUMPRODUCT((AttendanceLog!$E$2:$E$5000=$A20)*(AttendanceLog!$C$2:$C$5000>=MAX($D20,Settings!$B$3))*((AttendanceLog!$I$2:$I$5000="")+(IFERROR(SEARCH(","&$C20&",",","&AttendanceLog!$I$2:$I$5000&","),0)>0)))) -> 2 | F20: =IF($A20="","",SUMPRODUCT((EventLog!$C$2:$C$5000>=MAX($D20,Settings!$B$3))*(EventLog!$C$2:$C$5000<=TODAY())*((EventLog!$F$2:$F$5000="")+(IFERROR(SEARCH(","&$C20&",",","&EventLog!$F$2:$F$5000&","),0)>0)))) -> 3 | G20: =IFERROR(E20/F20,0) -> 0.66666667 | H20: =IFERROR(__xludf.DUMMYFUNCTION("IFERROR(MAX(FILTER(AttendanceLog!$C:$C,AttendanceLog!$E:$E=$A20,(AttendanceLog!$I:$I="""")+(IFERROR(SEARCH("",""&$C20&"","","",""&AttendanceLog!$I:$I&"",""),0)>0))),"""")"),46289.33333333333) -> 46289.333
A21: 2025P088 | B21: Active | C21: Dorm A | D21: 46265.333 | E21: =IF($A21="","",SUMPRODUCT((AttendanceLog!$E$2:$E$5000=$A21)*(AttendanceLog!$C$2:$C$5000>=MAX($D21,Settings!$B$3))*((AttendanceLog!$I$2:$I$5000="")+(IFERROR(SEARCH(","&$C21&",",","&AttendanceLog!$I$2:$I$5000&","),0)>0)))) -> 0 | F21: =IF($A21="","",SUMPRODUCT((EventLog!$C$2:$C$5000>=MAX($D21,Settings!$B$3))*(EventLog!$C$2:$C$5000<=TODAY())*((EventLog!$F$2:$F$5000="")+(IFERROR(SEARCH(","&$C21&",",","&EventLog!$F$2:$F$5000&","),0)>0)))) -> 3 | G21: =IFERROR(E21/F21,0) -> 0 | H21: =IFERROR(__xludf.DUMMYFUNCTION("IFERROR(MAX(FILTER(AttendanceLog!$C:$C,AttendanceLog!$E:$E=$A21,(AttendanceLog!$I:$I="""")+(IFERROR(SEARCH("",""&$C21&"","","",""&AttendanceLog!$I:$I&"",""),0)>0))),"""")"),"")
A22: 2026B057 | B22: Active | C22: Dorm A | D22: 46265.333 | E22: =IF($A22="","",SUMPRODUCT((AttendanceLog!$E$2:$E$5000=$A22)*(AttendanceLog!$C$2:$C$5000>=MAX($D22,Settings!$B$3))*((AttendanceLog!$I$2:$I$5000="")+(IFERROR(SEARCH(","&$C22&",",","&AttendanceLog!$I$2:$I$5000&","),0)>0)))) -> 0 | F22: =IF($A22="","",SUMPRODUCT((EventLog!$C$2:$C$5000>=MAX($D22,Settings!$B$3))*(EventLog!$C$2:$C$5000<=TODAY())*((EventLog!$F$2:$F$5000="")+(IFERROR(SEARCH(","&$C22&",",","&EventLog!$F$2:$F$5000&","),0)>0)))) -> 3 | G22: =IFERROR(E22/F22,0) -> 0 | H22: =IFERROR(__xludf.DUMMYFUNCTION("IFERROR(MAX(FILTER(AttendanceLog!$C:$C,AttendanceLog!$E:$E=$A22,(AttendanceLog!$I:$I="""")+(IFERROR(SEARCH("",""&$C22&"","","",""&AttendanceLog!$I:$I&"",""),0)>0))),"""")"),"")
A23: 2026B616 | B23: Active | C23: Dorm A | D23: 46265.333 | E23: =IF($A23="","",SUMPRODUCT((AttendanceLog!$E$2:$E$5000=$A23)*(AttendanceLog!$C$2:$C$5000>=MAX($D23,Settings!$B$3))*((AttendanceLog!$I$2:$I$5000="")+(IFERROR(SEARCH(","&$C23&",",","&AttendanceLog!$I$2:$I$5000&","),0)>0)))) -> 2 | F23: =IF($A23="","",SUMPRODUCT((EventLog!$C$2:$C$5000>=MAX($D23,Settings!$B$3))*(EventLog!$C$2:$C$5000<=TODAY())*((EventLog!$F$2:$F$5000="")+(IFERROR(SEARCH(","&$C23&",",","&EventLog!$F$2:$F$5000&","),0)>0)))) -> 3 | G23: =IFERROR(E23/F23,0) -> 0.66666667 | H23: =IFERROR(__xludf.DUMMYFUNCTION("IFERROR(MAX(FILTER(AttendanceLog!$C:$C,AttendanceLog!$E:$E=$A23,(AttendanceLog!$I:$I="""")+(IFERROR(SEARCH("",""&$C23&"","","",""&AttendanceLog!$I:$I&"",""),0)>0))),"""")"),46305.33333333333) -> 46305.333
A24: 2026B658 | B24: Active | C24: Dorm A | D24: 46265.333 | E24: =IF($A24="","",SUMPRODUCT((AttendanceLog!$E$2:$E$5000=$A24)*(AttendanceLog!$C$2:$C$5000>=MAX($D24,Settings!$B$3))*((AttendanceLog!$I$2:$I$5000="")+(IFERROR(SEARCH(","&$C24&",",","&AttendanceLog!$I$2:$I$5000&","),0)>0)))) -> 1 | F24: =IF($A24="","",SUMPRODUCT((EventLog!$C$2:$C$5000>=MAX($D24,Settings!$B$3))*(EventLog!$C$2:$C$5000<=TODAY())*((EventLog!$F$2:$F$5000="")+(IFERROR(SEARCH(","&$C24&",",","&EventLog!$F$2:$F$5000&","),0)>0)))) -> 3 | G24: =IFERROR(E24/F24,0) -> 0.33333333 | H24: =IFERROR(__xludf.DUMMYFUNCTION("IFERROR(MAX(FILTER(AttendanceLog!$C:$C,AttendanceLog!$E:$E=$A24,(AttendanceLog!$I:$I="""")+(IFERROR(SEARCH("",""&$C24&"","","",""&AttendanceLog!$I:$I&"",""),0)>0))),"""")"),46275.0) -> 46275
A25: 2026B692 | B25: Active | C25: Dorm A | D25: 46265.333 | E25: =IF($A25="","",SUMPRODUCT((AttendanceLog!$E$2:$E$5000=$A25)*(AttendanceLog!$C$2:$C$5000>=MAX($D25,Settings!$B$3))*((AttendanceLog!$I$2:$I$5000="")+(IFERROR(SEARCH(","&$C25&",",","&AttendanceLog!$I$2:$I$5000&","),0)>0)))) -> 0 | F25: =IF($A25="","",SUMPRODUCT((EventLog!$C$2:$C$5000>=MAX($D25,Settings!$B$3))*(EventLog!$C$2:$C$5000<=TODAY())*((EventLog!$F$2:$F$5000="")+(IFERROR(SEARCH(","&$C25&",",","&EventLog!$F$2:$F$5000&","),0)>0)))) -> 3 | G25: =IFERROR(E25/F25,0) -> 0 | H25: =IFERROR(__xludf.DUMMYFUNCTION("IFERROR(MAX(FILTER(AttendanceLog!$C:$C,AttendanceLog!$E:$E=$A25,(AttendanceLog!$I:$I="""")+(IFERROR(SEARCH("",""&$C25&"","","",""&AttendanceLog!$I:$I&"",""),0)>0))),"""")"),"")
A26: 2026B706 | B26: Active | C26: Dorm A | D26: 46265.333 | E26: =IF($A26="","",SUMPRODUCT((AttendanceLog!$E$2:$E$5000=$A26)*(AttendanceLog!$C$2:$C$5000>=MAX($D26,Settings!$B$3))*((AttendanceLog!$I$2:$I$5000="")+(IFERROR(SEARCH(","&$C26&",",","&AttendanceLog!$I$2:$I$5000&","),0)>0)))) -> 2 | F26: =IF($A26="","",SUMPRODUCT((EventLog!$C$2:$C$5000>=MAX($D26,Settings!$B$3))*(EventLog!$C$2:$C$5000<=TODAY())*((EventLog!$F$2:$F$5000="")+(IFERROR(SEARCH(","&$C26&",",","&EventLog!$F$2:$F$5000&","),0)>0)))) -> 3 | G26: =IFERROR(E26/F26,0) -> 0.66666667 | H26: =IFERROR(__xludf.DUMMYFUNCTION("IFERROR(MAX(FILTER(AttendanceLog!$C:$C,AttendanceLog!$E:$E=$A26,(AttendanceLog!$I:$I="""")+(IFERROR(SEARCH("",""&$C26&"","","",""&AttendanceLog!$I:$I&"",""),0)>0))),"""")"),46305.33333333333) -> 46305.333
A27: 2026B707 | B27: Active | C27: Dorm A | D27: 46265.333 | E27: =IF($A27="","",SUMPRODUCT((AttendanceLog!$E$2:$E$5000=$A27)*(AttendanceLog!$C$2:$C$5000>=MAX($D27,Settings!$B$3))*((AttendanceLog!$I$2:$I$5000="")+(IFERROR(SEARCH(","&$C27&",",","&AttendanceLog!$I$2:$I$5000&","),0)>0)))) -> 2 | F27: =IF($A27="","",SUMPRODUCT((EventLog!$C$2:$C$5000>=MAX($D27,Settings!$B$3))*(EventLog!$C$2:$C$5000<=TODAY())*((EventLog!$F$2:$F$5000="")+(IFERROR(SEARCH(","&$C27&",",","&EventLog!$F$2:$F$5000&","),0)>0)))) -> 3 | G27: =IFERROR(E27/F27,0) -> 0.66666667 | H27: =IFERROR(__xludf.DUMMYFUNCTION("IFERROR(MAX(FILTER(AttendanceLog!$C:$C,AttendanceLog!$E:$E=$A27,(AttendanceLog!$I:$I="""")+(IFERROR(SEARCH("",""&$C27&"","","",""&AttendanceLog!$I:$I&"",""),0)>0))),"""")"),46305.33333333333) -> 46305.333
A28: 2026M029 | B28: Active | C28: Dorm A | D28: 46265.333 | E28: =IF($A28="","",SUMPRODUCT((AttendanceLog!$E$2:$E$5000=$A28)*(AttendanceLog!$C$2:$C$5000>=MAX($D28,Settings!$B$3))*((AttendanceLog!$I$2:$I$5000="")+(IFERROR(SEARCH(","&$C28&",",","&AttendanceLog!$I$2:$I$5000&","),0)>0)))) -> 0 | F28: =IF($A28="","",SUMPRODUCT((EventLog!$C$2:$C$5000>=MAX($D28,Settings!$B$3))*(EventLog!$C$2:$C$5000<=TODAY())*((EventLog!$F$2:$F$5000="")+(IFERROR(SEARCH(","&$C28&",",","&EventLog!$F$2:$F$5000&","),0)>0)))) -> 3 | G28: =IFERROR(E28/F28,0) -> 0 | H28: =IFERROR(__xludf.DUMMYFUNCTION("IFERROR(MAX(FILTER(AttendanceLog!$C:$C,AttendanceLog!$E:$E=$A28,(AttendanceLog!$I:$I="""")+(IFERROR(SEARCH("",""&$C28&"","","",""&AttendanceLog!$I:$I&"",""),0)>0))),"""")"),"")
A29: 2026M607 | B29: Active | C29: Dorm A | D29: 46265.333 | E29: =IF($A29="","",SUMPRODUCT((AttendanceLog!$E$2:$E$5000=$A29)*(AttendanceLog!$C$2:$C$5000>=MAX($D29,Settings!$B$3))*((AttendanceLog!$I$2:$I$5000="")+(IFERROR(SEARCH(","&$C29&",",","&AttendanceLog!$I$2:$I$5000&","),0)>0)))) -> 0 | F29: =IF($A29="","",SUMPRODUCT((EventLog!$C$2:$C$5000>=MAX($D29,Settings!$B$3))*(EventLog!$C$2:$C$5000<=TODAY())*((EventLog!$F$2:$F$5000="")+(IFERROR(SEARCH(","&$C29&",",","&EventLog!$F$2:$F$5000&","),0)>0)))) -> 3 | G29: =IFERROR(E29/F29,0) -> 0 | H29: =IFERROR(__xludf.DUMMYFUNCTION("IFERROR(MAX(FILTER(AttendanceLog!$C:$C,AttendanceLog!$E:$E=$A29,(AttendanceLog!$I:$I="""")+(IFERROR(SEARCH("",""&$C29&"","","",""&AttendanceLog!$I:$I&"",""),0)>0))),"""")"),"")
A30: 2026M616 | B30: Active | C30: Dorm A | D30: 46265.333 | E30: =IF($A30="","",SUMPRODUCT((AttendanceLog!$E$2:$E$5000=$A30)*(AttendanceLog!$C$2:$C$5000>=MAX($D30,Settings!$B$3))*((AttendanceLog!$I$2:$I$5000="")+(IFERROR(SEARCH(","&$C30&",",","&AttendanceLog!$I$2:$I$5000&","),0)>0)))) -> 1 | F30: =IF($A30="","",SUMPRODUCT((EventLog!$C$2:$C$5000>=MAX($D30,Settings!$B$3))*(EventLog!$C$2:$C$5000<=TODAY())*((EventLog!$F$2:$F$5000="")+(IFERROR(SEARCH(","&$C30&",",","&EventLog!$F$2:$F$5000&","),0)>0)))) -> 3 | G30: =IFERROR(E30/F30,0) -> 0.33333333 | H30: =IFERROR(__xludf.DUMMYFUNCTION("IFERROR(MAX(FILTER(AttendanceLog!$C:$C,AttendanceLog!$E:$E=$A30,(AttendanceLog!$I:$I="""")+(IFERROR(SEARCH("",""&$C30&"","","",""&AttendanceLog!$I:$I&"",""),0)>0))),"""")"),46305.33333333333) -> 46305.333
A31: 2026M624 | B31: Active | C31: Dorm A | D31: 46265.333 | E31: =IF($A31="","",SUMPRODUCT((AttendanceLog!$E$2:$E$5000=$A31)*(AttendanceLog!$C$2:$C$5000>=MAX($D31,Settings!$B$3))*((AttendanceLog!$I$2:$I$5000="")+(IFERROR(SEARCH(","&$C31&",",","&AttendanceLog!$I$2:$I$5000&","),0)>0)))) -> 0 | F31: =IF($A31="","",SUMPRODUCT((EventLog!$C$2:$C$5000>=MAX($D31,Settings!$B$3))*(EventLog!$C$2:$C$5000<=TODAY())*((EventLog!$F$2:$F$5000="")+(IFERROR(SEARCH(","&$C31&",",","&EventLog!$F$2:$F$5000&","),0)>0)))) -> 3 | G31: =IFERROR(E31/F31,0) -> 0 | H31: =IFERROR(__xludf.DUMMYFUNCTION("IFERROR(MAX(FILTER(AttendanceLog!$C:$C,AttendanceLog!$E:$E=$A31,(AttendanceLog!$I:$I="""")+(IFERROR(SEARCH("",""&$C31&"","","",""&AttendanceLog!$I:$I&"",""),0)>0))),"""")"),"")
A32: 2026M628 | B32: Active | C32: Dorm A | D32: 46265.333 | E32: =IF($A32="","",SUMPRODUCT((AttendanceLog!$E$2:$E$5000=$A32)*(AttendanceLog!$C$2:$C$5000>=MAX($D32,Settings!$B$3))*((AttendanceLog!$I$2:$I$5000="")+(IFERROR(SEARCH(","&$C32&",",","&AttendanceLog!$I$2:$I$5000&","),0)>0)))) -> 1 | F32: =IF($A32="","",SUMPRODUCT((EventLog!$C$2:$C$5000>=MAX($D32,Settings!$B$3))*(EventLog!$C$2:$C$5000<=TODAY())*((EventLog!$F$2:$F$5000="")+(IFERROR(SEARCH(","&$C32&",",","&EventLog!$F$2:$F$5000&","),0)>0)))) -> 3 | G32: =IFERROR(E32/F32,0) -> 0.33333333 | H32: =IFERROR(__xludf.DUMMYFUNCTION("IFERROR(MAX(FILTER(AttendanceLog!$C:$C,AttendanceLog!$E:$E=$A32,(AttendanceLog!$I:$I="""")+(IFERROR(SEARCH("",""&$C32&"","","",""&AttendanceLog!$I:$I&"",""),0)>0))),"""")"),46305.33333333333) -> 46305.333
A33: 2026M631 | B33: Active | C33: Dorm A | D33: 46265.333 | E33: =IF($A33="","",SUMPRODUCT((AttendanceLog!$E$2:$E$5000=$A33)*(AttendanceLog!$C$2:$C$5000>=MAX($D33,Settings!$B$3))*((AttendanceLog!$I$2:$I$5000="")+(IFERROR(SEARCH(","&$C33&",",","&AttendanceLog!$I$2:$I$5000&","),0)>0)))) -> 3 | F33: =IF($A33="","",SUMPRODUCT((EventLog!$C$2:$C$5000>=MAX($D33,Settings!$B$3))*(EventLog!$C$2:$C$5000<=TODAY())*((EventLog!$F$2:$F$5000="")+(IFERROR(SEARCH(","&$C33&",",","&EventLog!$F$2:$F$5000&","),0)>0)))) -> 3 | G33: =IFERROR(E33/F33,0) -> 1 | H33: =IFERROR(__xludf.DUMMYFUNCTION("IFERROR(MAX(FILTER(AttendanceLog!$C:$C,AttendanceLog!$E:$E=$A33,(AttendanceLog!$I:$I="""")+(IFERROR(SEARCH("",""&$C33&"","","",""&AttendanceLog!$I:$I&"",""),0)>0))),"""")"),46305.33333333333) -> 46305.333
A34: 2026M632 | B34: Active | C34: Dorm A | D34: 46265.333 | E34: =IF($A34="","",SUMPRODUCT((AttendanceLog!$E$2:$E$5000=$A34)*(AttendanceLog!$C$2:$C$5000>=MAX($D34,Settings!$B$3))*((AttendanceLog!$I$2:$I$5000="")+(IFERROR(SEARCH(","&$C34&",",","&AttendanceLog!$I$2:$I$5000&","),0)>0)))) -> 1 | F34: =IF($A34="","",SUMPRODUCT((EventLog!$C$2:$C$5000>=MAX($D34,Settings!$B$3))*(EventLog!$C$2:$C$5000<=TODAY())*((EventLog!$F$2:$F$5000="")+(IFERROR(SEARCH(","&$C34&",",","&EventLog!$F$2:$F$5000&","),0)>0)))) -> 3 | G34: =IFERROR(E34/F34,0) -> 0.33333333 | H34: =IFERROR(__xludf.DUMMYFUNCTION("IFERROR(MAX(FILTER(AttendanceLog!$C:$C,AttendanceLog!$E:$E=$A34,(AttendanceLog!$I:$I="""")+(IFERROR(SEARCH("",""&$C34&"","","",""&AttendanceLog!$I:$I&"",""),0)>0))),"""")"),46305.33333333333) -> 46305.333
A35: 2026M633 | B35: Active | C35: Dorm A | D35: 46265.333 | E35: =IF($A35="","",SUMPRODUCT((AttendanceLog!$E$2:$E$5000=$A35)*(AttendanceLog!$C$2:$C$5000>=MAX($D35,Settings!$B$3))*((AttendanceLog!$I$2:$I$5000="")+(IFERROR(SEARCH(","&$C35&",",","&AttendanceLog!$I$2:$I$5000&","),0)>0)))) -> 3 | F35: =IF($A35="","",SUMPRODUCT((EventLog!$C$2:$C$5000>=MAX($D35,Settings!$B$3))*(EventLog!$C$2:$C$5000<=TODAY())*((EventLog!$F$2:$F$5000="")+(IFERROR(SEARCH(","&$C35&",",","&EventLog!$F$2:$F$5000&","),0)>0)))) -> 3 | G35: =IFERROR(E35/F35,0) -> 1 | H35: =IFERROR(__xludf.DUMMYFUNCTION("IFERROR(MAX(FILTER(AttendanceLog!$C:$C,AttendanceLog!$E:$E=$A35,(AttendanceLog!$I:$I="""")+(IFERROR(SEARCH("",""&$C35&"","","",""&AttendanceLog!$I:$I&"",""),0)>0))),"""")"),46305.33333333333) -> 46305.333
A36: 2026M634 | B36: Active | C36: Dorm A | D36: 46265.333 | E36: =IF($A36="","",SUMPRODUCT((AttendanceLog!$E$2:$E$5000=$A36)*(AttendanceLog!$C$2:$C$5000>=MAX($D36,Settings!$B$3))*((AttendanceLog!$I$2:$I$5000="")+(IFERROR(SEARCH(","&$C36&",",","&AttendanceLog!$I$2:$I$5000&","),0)>0)))) -> 0 | F36: =IF($A36="","",SUMPRODUCT((EventLog!$C$2:$C$5000>=MAX($D36,Settings!$B$3))*(EventLog!$C$2:$C$5000<=TODAY())*((EventLog!$F$2:$F$5000="")+(IFERROR(SEARCH(","&$C36&",",","&EventLog!$F$2:$F$5000&","),0)>0)))) -> 3 | G36: =IFERROR(E36/F36,0) -> 0 | H36: =IFERROR(__xludf.DUMMYFUNCTION("IFERROR(MAX(FILTER(AttendanceLog!$C:$C,AttendanceLog!$E:$E=$A36,(AttendanceLog!$I:$I="""")+(IFERROR(SEARCH("",""&$C36&"","","",""&AttendanceLog!$I:$I&"",""),0)>0))),"""")"),"")
A37: 2026M640 | B37: Active | C37: Dorm A | D37: 46265.333 | E37: =IF($A37="","",SUMPRODUCT((AttendanceLog!$E$2:$E$5000=$A37)*(AttendanceLog!$C$2:$C$5000>=MAX($D37,Settings!$B$3))*((AttendanceLog!$I$2:$I$5000="")+(IFERROR(SEARCH(","&$C37&",",","&AttendanceLog!$I$2:$I$5000&","),0)>0)))) -> 2 | F37: =IF($A37="","",SUMPRODUCT((EventLog!$C$2:$C$5000>=MAX($D37,Settings!$B$3))*(EventLog!$C$2:$C$5000<=TODAY())*((EventLog!$F$2:$F$5000="")+(IFERROR(SEARCH(","&$C37&",",","&EventLog!$F$2:$F$5000&","),0)>0)))) -> 3 | G37: =IFERROR(E37/F37,0) -> 0.66666667 | H37: =IFERROR(__xludf.DUMMYFUNCTION("IFERROR(MAX(FILTER(AttendanceLog!$C:$C,AttendanceLog!$E:$E=$A37,(AttendanceLog!$I:$I="""")+(IFERROR(SEARCH("",""&$C37&"","","",""&AttendanceLog!$I:$I&"",""),0)>0))),"""")"),46305.33333333333) -> 46305.333
A38: 2026M653 | B38: Active | C38: Dorm A | D38: 46265.333 | E38: =IF($A38="","",SUMPRODUCT((AttendanceLog!$E$2:$E$5000=$A38)*(AttendanceLog!$C$2:$C$5000>=MAX($D38,Settings!$B$3))*((AttendanceLog!$I$2:$I$5000="")+(IFERROR(SEARCH(","&$C38&",",","&AttendanceLog!$I$2:$I$5000&","),0)>0)))) -> 2 | F38: =IF($A38="","",SUMPRODUCT((EventLog!$C$2:$C$5000>=MAX($D38,Settings!$B$3))*(EventLog!$C$2:$C$5000<=TODAY())*((EventLog!$F$2:$F$5000="")+(IFERROR(SEARCH(","&$C38&",",","&EventLog!$F$2:$F$5000&","),0)>0)))) -> 3 | G38: =IFERROR(E38/F38,0) -> 0.66666667 | H38: =IFERROR(__xludf.DUMMYFUNCTION("IFERROR(MAX(FILTER(AttendanceLog!$C:$C,AttendanceLog!$E:$E=$A38,(AttendanceLog!$I:$I="""")+(IFERROR(SEARCH("",""&$C38&"","","",""&AttendanceLog!$I:$I&"",""),0)>0))),"""")"),46305.33333333333) -> 46305.333
A39: 2026M656 | B39: Active | C39: Dorm A | D39: 46265.333 | E39: =IF($A39="","",SUMPRODUCT((AttendanceLog!$E$2:$E$5000=$A39)*(AttendanceLog!$C$2:$C$5000>=MAX($D39,Settings!$B$3))*((AttendanceLog!$I$2:$I$5000="")+(IFERROR(SEARCH(","&$C39&",",","&AttendanceLog!$I$2:$I$5000&","),0)>0)))) -> 3 | F39: =IF($A39="","",SUMPRODUCT((EventLog!$C$2:$C$5000>=MAX($D39,Settings!$B$3))*(EventLog!$C$2:$C$5000<=TODAY())*((EventLog!$F$2:$F$5000="")+(IFERROR(SEARCH(","&$C39&",",","&EventLog!$F$2:$F$5000&","),0)>0)))) -> 3 | G39: =IFERROR(E39/F39,0) -> 1 | H39: =IFERROR(__xludf.DUMMYFUNCTION("IFERROR(MAX(FILTER(AttendanceLog!$C:$C,AttendanceLog!$E:$E=$A39,(AttendanceLog!$I:$I="""")+(IFERROR(SEARCH("",""&$C39&"","","",""&AttendanceLog!$I:$I&"",""),0)>0))),"""")"),46305.33333333333) -> 46305.333
A40: 2026M660 | B40: Active | C40: Dorm A | D40: 46265.333 | E40: =IF($A40="","",SUMPRODUCT((AttendanceLog!$E$2:$E$5000=$A40)*(AttendanceLog!$C$2:$C$5000>=MAX($D40,Settings!$B$3))*((AttendanceLog!$I$2:$I$5000="")+(IFERROR(SEARCH(","&$C40&",",","&AttendanceLog!$I$2:$I$5000&","),0)>0)))) -> 1 | F40: =IF($A40="","",SUMPRODUCT((EventLog!$C$2:$C$5000>=MAX($D40,Settings!$B$3))*(EventLog!$C$2:$C$5000<=TODAY())*((EventLog!$F$2:$F$5000="")+(IFERROR(SEARCH(","&$C40&",",","&EventLog!$F$2:$F$5000&","),0)>0)))) -> 3 | G40: =IFERROR(E40/F40,0) -> 0.33333333 | H40: =IFERROR(__xludf.DUMMYFUNCTION("IFERROR(MAX(FILTER(AttendanceLog!$C:$C,AttendanceLog!$E:$E=$A40,(AttendanceLog!$I:$I="""")+(IFERROR(SEARCH("",""&$C40&"","","",""&AttendanceLog!$I:$I&"",""),0)>0))),"""")"),46305.33333333333) -> 46305.333
A41: 2026M664 | B41: Active | C41: Dorm A | D41: 46265.333 | E41: =IF($A41="","",SUMPRODUCT((AttendanceLog!$E$2:$E$5000=$A41)*(AttendanceLog!$C$2:$C$5000>=MAX($D41,Settings!$B$3))*((AttendanceLog!$I$2:$I$5000="")+(IFERROR(SEARCH(","&$C41&",",","&AttendanceLog!$I$2:$I$5000&","),0)>0)))) -> 1 | F41: =IF($A41="","",SUMPRODUCT((EventLog!$C$2:$C$5000>=MAX($D41,Settings!$B$3))*(EventLog!$C$2:$C$5000<=TODAY())*((EventLog!$F$2:$F$5000="")+(IFERROR(SEARCH(","&$C41&",",","&EventLog!$F$2:$F$5000&","),0)>0)))) -> 3 | G41: =IFERROR(E41/F41,0) -> 0.33333333 | H41: =IFERROR(__xludf.DUMMYFUNCTION("IFERROR(MAX(FILTER(AttendanceLog!$C:$C,AttendanceLog!$E:$E=$A41,(AttendanceLog!$I:$I="""")+(IFERROR(SEARCH("",""&$C41&"","","",""&AttendanceLog!$I:$I&"",""),0)>0))),"""")"),46275.0) -> 46275
...

Sheet Dorm B
A1: Dorm B Attendance Summary
A2: Dorm Group Attendance Score | B2: =IFERROR(SUM(E5:E1000)/SUM(F5:F1000),0) -> 0.37755102 | D2: Academic Year Start | E2: =Settings!B3 -> 46266
A4: Student ID | B4: Status | C4: Dorm | D4: Start Date | E4: Events Attended | F4: Eligible Events | G4: Attendance % | H4: Last Attended
A5: 2.026e+128 | B5: Active | C5: Dorm B | D5: 46236.333 | E5: =IF($A5="","",SUMPRODUCT((AttendanceLog!$E$2:$E$5000=$A5)*(AttendanceLog!$C$2:$C$5000>=MAX($D5,Settings!$B$3))*((AttendanceLog!$I$2:$I$5000="")+(IFERROR(SEARCH(","&$C5&",",","&AttendanceLog!$I$2:$I$5000&","),0)>0)))) -> 0 | F5: =IF($A5="","",SUMPRODUCT((EventLog!$C$2:$C$5000>=MAX($D5,Settings!$B$3))*(EventLog!$C$2:$C$5000<=TODAY())*((EventLog!$F$2:$F$5000="")+(IFERROR(SEARCH(","&$C5&",",","&EventLog!$F$2:$F$5000&","),0)>0)))) -> 4 | G5: =IFERROR(E5/F5,0) -> 0 | H5: =IFERROR(__xludf.DUMMYFUNCTION("IFERROR(MAX(FILTER(AttendanceLog!$C:$C,AttendanceLog!$E:$E=$A5,(AttendanceLog!$I:$I="""")+(IFERROR(SEARCH("",""&$C5&"","","",""&AttendanceLog!$I:$I&"",""),0)>0))),"""")"),"")
A6: 2023M620 | B6: Active | C6: Dorm B | D6: 46235.333 | E6: =IF($A6="","",SUMPRODUCT((AttendanceLog!$E$2:$E$5000=$A6)*(AttendanceLog!$C$2:$C$5000>=MAX($D6,Settings!$B$3))*((AttendanceLog!$I$2:$I$5000="")+(IFERROR(SEARCH(","&$C6&",",","&AttendanceLog!$I$2:$I$5000&","),0)>0)))) -> 0 | F6: =IF($A6="","",SUMPRODUCT((EventLog!$C$2:$C$5000>=MAX($D6,Settings!$B$3))*(EventLog!$C$2:$C$5000<=TODAY())*((EventLog!$F$2:$F$5000="")+(IFERROR(SEARCH(","&$C6&",",","&EventLog!$F$2:$F$5000&","),0)>0)))) -> 4 | G6: =IFERROR(E6/F6,0) -> 0 | H6: =IFERROR(__xludf.DUMMYFUNCTION("IFERROR(MAX(FILTER(AttendanceLog!$C:$C,AttendanceLog!$E:$E=$A6,(AttendanceLog!$I:$I="""")+(IFERROR(SEARCH("",""&$C6&"","","",""&AttendanceLog!$I:$I&"",""),0)>0))),"""")"),"")
A7: 2023M676 | B7: Active | C7: Dorm B | D7: 46235.333 | E7: =IF($A7="","",SUMPRODUCT((AttendanceLog!$E$2:$E$5000=$A7)*(AttendanceLog!$C$2:$C$5000>=MAX($D7,Settings!$B$3))*((AttendanceLog!$I$2:$I$5000="")+(IFERROR(SEARCH(","&$C7&",",","&AttendanceLog!$I$2:$I$5000&","),0)>0)))) -> 0 | F7: =IF($A7="","",SUMPRODUCT((EventLog!$C$2:$C$5000>=MAX($D7,Settings!$B$3))*(EventLog!$C$2:$C$5000<=TODAY())*((EventLog!$F$2:$F$5000="")+(IFERROR(SEARCH(","&$C7&",",","&EventLog!$F$2:$F$5000&","),0)>0)))) -> 4 | G7: =IFERROR(E7/F7,0) -> 0 | H7: =IFERROR(__xludf.DUMMYFUNCTION("IFERROR(MAX(FILTER(AttendanceLog!$C:$C,AttendanceLog!$E:$E=$A7,(AttendanceLog!$I:$I="""")+(IFERROR(SEARCH("",""&$C7&"","","",""&AttendanceLog!$I:$I&"",""),0)>0))),"""")"),"")
A8: 2024H502 | B8: Active | C8: Dorm B | D8: 46235.333 | E8: =IF($A8="","",SUMPRODUCT((AttendanceLog!$E$2:$E$5000=$A8)*(AttendanceLog!$C$2:$C$5000>=MAX($D8,Settings!$B$3))*((AttendanceLog!$I$2:$I$5000="")+(IFERROR(SEARCH(","&$C8&",",","&AttendanceLog!$I$2:$I$5000&","),0)>0)))) -> 0 | F8: =IF($A8="","",SUMPRODUCT((EventLog!$C$2:$C$5000>=MAX($D8,Settings!$B$3))*(EventLog!$C$2:$C$5000<=TODAY())*((EventLog!$F$2:$F$5000="")+(IFERROR(SEARCH(","&$C8&",",","&EventLog!$F$2:$F$5000&","),0)>0)))) -> 4 | G8: =IFERROR(E8/F8,0) -> 0 | H8: =IFERROR(__xludf.DUMMYFUNCTION("IFERROR(MAX(FILTER(AttendanceLog!$C:$C,AttendanceLog!$E:$E=$A8,(AttendanceLog!$I:$I="""")+(IFERROR(SEARCH("",""&$C8&"","","",""&AttendanceLog!$I:$I&"",""),0)>0))),"""")"),"")
A9: 2024MD02 | B9: Active | C9: Dorm B | D9: 46239.333 | E9: =IF($A9="","",SUMPRODUCT((AttendanceLog!$E$2:$E$5000=$A9)*(AttendanceLog!$C$2:$C$5000>=MAX($D9,Settings!$B$3))*((AttendanceLog!$I$2:$I$5000="")+(IFERROR(SEARCH(","&$C9&",",","&AttendanceLog!$I$2:$I$5000&","),0)>0)))) -> 0 | F9: =IF($A9="","",SUMPRODUCT((EventLog!$C$2:$C$5000>=MAX($D9,Settings!$B$3))*(EventLog!$C$2:$C$5000<=TODAY())*((EventLog!$F$2:$F$5000="")+(IFERROR(SEARCH(","&$C9&",",","&EventLog!$F$2:$F$5000&","),0)>0)))) -> 4 | G9: =IFERROR(E9/F9,0) -> 0 | H9: =IFERROR(__xludf.DUMMYFUNCTION("IFERROR(MAX(FILTER(AttendanceLog!$C:$C,AttendanceLog!$E:$E=$A9,(AttendanceLog!$I:$I="""")+(IFERROR(SEARCH("",""&$C9&"","","",""&AttendanceLog!$I:$I&"",""),0)>0))),"""")"),"")
A10: 2025B638 | B10: Active | C10: Dorm B | D10: 46235.333 | E10: =IF($A10="","",SUMPRODUCT((AttendanceLog!$E$2:$E$5000=$A10)*(AttendanceLog!$C$2:$C$5000>=MAX($D10,Settings!$B$3))*((AttendanceLog!$I$2:$I$5000="")+(IFERROR(SEARCH(","&$C10&",",","&AttendanceLog!$I$2:$I$5000&","),0)>0)))) -> 0 | F10: =IF($A10="","",SUMPRODUCT((EventLog!$C$2:$C$5000>=MAX($D10,Settings!$B$3))*(EventLog!$C$2:$C$5000<=TODAY())*((EventLog!$F$2:$F$5000="")+(IFERROR(SEARCH(","&$C10&",",","&EventLog!$F$2:$F$5000&","),0)>0)))) -> 4 | G10: =IFERROR(E10/F10,0) -> 0 | H10: =IFERROR(__xludf.DUMMYFUNCTION("IFERROR(MAX(FILTER(AttendanceLog!$C:$C,AttendanceLog!$E:$E=$A10,(AttendanceLog!$I:$I="""")+(IFERROR(SEARCH("",""&$C10&"","","",""&AttendanceLog!$I:$I&"",""),0)>0))),"""")"),"")
A11: 2025H020 | B11: Active | C11: Dorm B | D11: 46235.333 | E11: =IF($A11="","",SUMPRODUCT((AttendanceLog!$E$2:$E$5000=$A11)*(AttendanceLog!$C$2:$C$5000>=MAX($D11,Settings!$B$3))*((AttendanceLog!$I$2:$I$5000="")+(IFERROR(SEARCH(","&$C11&",",","&AttendanceLog!$I$2:$I$5000&","),0)>0)))) -> 0 | F11: =IF($A11="","",SUMPRODUCT((EventLog!$C$2:$C$5000>=MAX($D11,Settings!$B$3))*(EventLog!$C$2:$C$5000<=TODAY())*((EventLog!$F$2:$F$5000="")+(IFERROR(SEARCH(","&$C11&",",","&EventLog!$F$2:$F$5000&","),0)>0)))) -> 4 | G11: =IFERROR(E11/F11,0) -> 0 | H11: =IFERROR(__xludf.DUMMYFUNCTION("IFERROR(MAX(FILTER(AttendanceLog!$C:$C,AttendanceLog!$E:$E=$A11,(AttendanceLog!$I:$I="""")+(IFERROR(SEARCH("",""&$C11&"","","",""&AttendanceLog!$I:$I&"",""),0)>0))),"""")"),"")
A12: 2025M002 | B12: Active | C12: Dorm B | D12: 46251.333 | E12: =IF($A12="","",SUMPRODUCT((AttendanceLog!$E$2:$E$5000=$A12)*(AttendanceLog!$C$2:$C$5000>=MAX($D12,Settings!$B$3))*((AttendanceLog!$I$2:$I$5000="")+(IFERROR(SEARCH(","&$C12&",",","&AttendanceLog!$I$2:$I$5000&","),0)>0)))) -> 0 | F12: =IF($A12="","",SUMPRODUCT((EventLog!$C$2:$C$5000>=MAX($D12,Settings!$B$3))*(EventLog!$C$2:$C$5000<=TODAY())*((EventLog!$F$2:$F$5000="")+(IFERROR(SEARCH(","&$C12&",",","&EventLog!$F$2:$F$5000&","),0)>0)))) -> 4 | G12: =IFERROR(E12/F12,0) -> 0 | H12: =IFERROR(__xludf.DUMMYFUNCTION("IFERROR(MAX(FILTER(AttendanceLog!$C:$C,AttendanceLog!$E:$E=$A12,(AttendanceLog!$I:$I="""")+(IFERROR(SEARCH("",""&$C12&"","","",""&AttendanceLog!$I:$I&"",""),0)>0))),"""")"),"")
A13: 2025M0605 | B13: Active | C13: Dorm B | D13: 46234.333 | E13: =IF($A13="","",SUMPRODUCT((AttendanceLog!$E$2:$E$5000=$A13)*(AttendanceLog!$C$2:$C$5000>=MAX($D13,Settings!$B$3))*((AttendanceLog!$I$2:$I$5000="")+(IFERROR(SEARCH(","&$C13&",",","&AttendanceLog!$I$2:$I$5000&","),0)>0)))) -> 0 | F13: =IF($A13="","",SUMPRODUCT((EventLog!$C$2:$C$5000>=MAX($D13,Settings!$B$3))*(EventLog!$C$2:$C$5000<=TODAY())*((EventLog!$F$2:$F$5000="")+(IFERROR(SEARCH(","&$C13&",",","&EventLog!$F$2:$F$5000&","),0)>0)))) -> 4 | G13: =IFERROR(E13/F13,0) -> 0 | H13: =IFERROR(__xludf.DUMMYFUNCTION("IFERROR(MAX(FILTER(AttendanceLog!$C:$C,AttendanceLog!$E:$E=$A13,(AttendanceLog!$I:$I="""")+(IFERROR(SEARCH("",""&$C13&"","","",""&AttendanceLog!$I:$I&"",""),0)>0))),"""")"),"")
A14: 2025M616 | B14: Active | C14: Dorm B | D14: 46235.333 | E14: =IF($A14="","",SUMPRODUCT((AttendanceLog!$E$2:$E$5000=$A14)*(AttendanceLog!$C$2:$C$5000>=MAX($D14,Settings!$B$3))*((AttendanceLog!$I$2:$I$5000="")+(IFERROR(SEARCH(","&$C14&",",","&AttendanceLog!$I$2:$I$5000&","),0)>0)))) -> 1 | F14: =IF($A14="","",SUMPRODUCT((EventLog!$C$2:$C$5000>=MAX($D14,Settings!$B$3))*(EventLog!$C$2:$C$5000<=TODAY())*((EventLog!$F$2:$F$5000="")+(IFERROR(SEARCH(","&$C14&",",","&EventLog!$F$2:$F$5000&","),0)>0)))) -> 4 | G14: =IFERROR(E14/F14,0) -> 0.25 | H14: =IFERROR(__xludf.DUMMYFUNCTION("IFERROR(MAX(FILTER(AttendanceLog!$C:$C,AttendanceLog!$E:$E=$A14,(AttendanceLog!$I:$I="""")+(IFERROR(SEARCH("",""&$C14&"","","",""&AttendanceLog!$I:$I&"",""),0)>0))),"""")"),46304.0) -> 46304
A15: 2025M749 | B15: Active | C15: Dorm B | D15: 46238.333 | E15: =IF($A15="","",SUMPRODUCT((AttendanceLog!$E$2:$E$5000=$A15)*(AttendanceLog!$C$2:$C$5000>=MAX($D15,Settings!$B$3))*((AttendanceLog!$I$2:$I$5000="")+(IFERROR(SEARCH(","&$C15&",",","&AttendanceLog!$I$2:$I$5000&","),0)>0)))) -> 0 | F15: =IF($A15="","",SUMPRODUCT((EventLog!$C$2:$C$5000>=MAX($D15,Settings!$B$3))*(EventLog!$C$2:$C$5000<=TODAY())*((EventLog!$F$2:$F$5000="")+(IFERROR(SEARCH(","&$C15&",",","&EventLog!$F$2:$F$5000&","),0)>0)))) -> 4 | G15: =IFERROR(E15/F15,0) -> 0 | H15: =IFERROR(__xludf.DUMMYFUNCTION("IFERROR(MAX(FILTER(AttendanceLog!$C:$C,AttendanceLog!$E:$E=$A15,(AttendanceLog!$I:$I="""")+(IFERROR(SEARCH("",""&$C15&"","","",""&AttendanceLog!$I:$I&"",""),0)>0))),"""")"),"")
A16: 2025V602 | B16: Active | C16: Dorm B | D16: 46235.333 | E16: =IF($A16="","",SUMPRODUCT((AttendanceLog!$E$2:$E$5000=$A16)*(AttendanceLog!$C$2:$C$5000>=MAX($D16,Settings!$B$3))*((AttendanceLog!$I$2:$I$5000="")+(IFERROR(SEARCH(","&$C16&",",","&AttendanceLog!$I$2:$I$5000&","),0)>0)))) -> 0 | F16: =IF($A16="","",SUMPRODUCT((EventLog!$C$2:$C$5000>=MAX($D16,Settings!$B$3))*(EventLog!$C$2:$C$5000<=TODAY())*((EventLog!$F$2:$F$5000="")+(IFERROR(SEARCH(","&$C16&",",","&EventLog!$F$2:$F$5000&","),0)>0)))) -> 4 | G16: =IFERROR(E16/F16,0) -> 0 | H16: =IFERROR(__xludf.DUMMYFUNCTION("IFERROR(MAX(FILTER(AttendanceLog!$C:$C,AttendanceLog!$E:$E=$A16,(AttendanceLog!$I:$I="""")+(IFERROR(SEARCH("",""&$C16&"","","",""&AttendanceLog!$I:$I&"",""),0)>0))),"""")"),"")
A17: 2026B165 | B17: Active | C17: Dorm B | D17: 46246.333 | E17: =IF($A17="","",SUMPRODUCT((AttendanceLog!$E$2:$E$5000=$A17)*(AttendanceLog!$C$2:$C$5000>=MAX($D17,Settings!$B$3))*((AttendanceLog!$I$2:$I$5000="")+(IFERROR(SEARCH(","&$C17&",",","&AttendanceLog!$I$2:$I$5000&","),0)>0)))) -> 0 | F17: =IF($A17="","",SUMPRODUCT((EventLog!$C$2:$C$5000>=MAX($D17,Settings!$B$3))*(EventLog!$C$2:$C$5000<=TODAY())*((EventLog!$F$2:$F$5000="")+(IFERROR(SEARCH(","&$C17&",",","&EventLog!$F$2:$F$5000&","),0)>0)))) -> 4 | G17: =IFERROR(E17/F17,0) -> 0 | H17: =IFERROR(__xludf.DUMMYFUNCTION("IFERROR(MAX(FILTER(AttendanceLog!$C:$C,AttendanceLog!$E:$E=$A17,(AttendanceLog!$I:$I="""")+(IFERROR(SEARCH("",""&$C17&"","","",""&AttendanceLog!$I:$I&"",""),0)>0))),"""")"),"")
A18: 2026B606 | B18: Active | C18: Dorm B | D18: 46252.333 | E18: =IF($A18="","",SUMPRODUCT((AttendanceLog!$E$2:$E$5000=$A18)*(AttendanceLog!$C$2:$C$5000>=MAX($D18,Settings!$B$3))*((AttendanceLog!$I$2:$I$5000="")+(IFERROR(SEARCH(","&$C18&",",","&AttendanceLog!$I$2:$I$5000&","),0)>0)))) -> 0 | F18: =IF($A18="","",SUMPRODUCT((EventLog!$C$2:$C$5000>=MAX($D18,Settings!$B$3))*(EventLog!$C$2:$C$5000<=TODAY())*((EventLog!$F$2:$F$5000="")+(IFERROR(SEARCH(","&$C18&",",","&EventLog!$F$2:$F$5000&","),0)>0)))) -> 4 | G18: =IFERROR(E18/F18,0) -> 0 | H18: =IFERROR(__xludf.DUMMYFUNCTION("IFERROR(MAX(FILTER(AttendanceLog!$C:$C,AttendanceLog!$E:$E=$A18,(AttendanceLog!$I:$I="""")+(IFERROR(SEARCH("",""&$C18&"","","",""&AttendanceLog!$I:$I&"",""),0)>0))),"""")"),"")
A19: 2026B607 | B19: Active | C19: Dorm B | D19: 46245.333 | E19: =IF($A19="","",SUMPRODUCT((AttendanceLog!$E$2:$E$5000=$A19)*(AttendanceLog!$C$2:$C$5000>=MAX($D19,Settings!$B$3))*((AttendanceLog!$I$2:$I$5000="")+(IFERROR(SEARCH(","&$C19&",",","&AttendanceLog!$I$2:$I$5000&","),0)>0)))) -> 1 | F19: =IF($A19="","",SUMPRODUCT((EventLog!$C$2:$C$5000>=MAX($D19,Settings!$B$3))*(EventLog!$C$2:$C$5000<=TODAY())*((EventLog!$F$2:$F$5000="")+(IFERROR(SEARCH(","&$C19&",",","&EventLog!$F$2:$F$5000&","),0)>0)))) -> 4 | G19: =IFERROR(E19/F19,0) -> 0.25 | H19: =IFERROR(__xludf.DUMMYFUNCTION("IFERROR(MAX(FILTER(AttendanceLog!$C:$C,AttendanceLog!$E:$E=$A19,(AttendanceLog!$I:$I="""")+(IFERROR(SEARCH("",""&$C19&"","","",""&AttendanceLog!$I:$I&"",""),0)>0))),"""")"),46305.33333333333) -> 46305.333
A20: 2026B643 | B20: Active | C20: Dorm B | D20: 46248.333 | E20: =IF($A20="","",SUMPRODUCT((AttendanceLog!$E$2:$E$5000=$A20)*(AttendanceLog!$C$2:$C$5000>=MAX($D20,Settings!$B$3))*((AttendanceLog!$I$2:$I$5000="")+(IFERROR(SEARCH(","&$C20&",",","&AttendanceLog!$I$2:$I$5000&","),0)>0)))) -> 4 | F20: =IF($A20="","",SUMPRODUCT((EventLog!$C$2:$C$5000>=MAX($D20,Settings!$B$3))*(EventLog!$C$2:$C$5000<=TODAY())*((EventLog!$F$2:$F$5000="")+(IFERROR(SEARCH(","&$C20&",",","&EventLog!$F$2:$F$5000&","),0)>0)))) -> 4 | G20: =IFERROR(E20/F20,0) -> 1 | H20: =IFERROR(__xludf.DUMMYFUNCTION("IFERROR(MAX(FILTER(AttendanceLog!$C:$C,AttendanceLog!$E:$E=$A20,(AttendanceLog!$I:$I="""")+(IFERROR(SEARCH("",""&$C20&"","","",""&AttendanceLog!$I:$I&"",""),0)>0))),"""")"),46306.0) -> 46306
A21: 2026B646 | B21: Active | C21: Dorm B | D21: 46250.333 | E21: =IF($A21="","",SUMPRODUCT((AttendanceLog!$E$2:$E$5000=$A21)*(AttendanceLog!$C$2:$C$5000>=MAX($D21,Settings!$B$3))*((AttendanceLog!$I$2:$I$5000="")+(IFERROR(SEARCH(","&$C21&",",","&AttendanceLog!$I$2:$I$5000&","),0)>0)))) -> 2 | F21: =IF($A21="","",SUMPRODUCT((EventLog!$C$2:$C$5000>=MAX($D21,Settings!$B$3))*(EventLog!$C$2:$C$5000<=TODAY())*((EventLog!$F$2:$F$5000="")+(IFERROR(SEARCH(","&$C21&",",","&EventLog!$F$2:$F$5000&","),0)>0)))) -> 4 | G21: =IFERROR(E21/F21,0) -> 0.5 | H21: =IFERROR(__xludf.DUMMYFUNCTION("IFERROR(MAX(FILTER(AttendanceLog!$C:$C,AttendanceLog!$E:$E=$A21,(AttendanceLog!$I:$I="""")+(IFERROR(SEARCH("",""&$C21&"","","",""&AttendanceLog!$I:$I&"",""),0)>0))),"""")"),46304.0) -> 46304
A22: 2026B660 | B22: Active | C22: Dorm B | D22: 46235.333 | E22: =IF($A22="","",SUMPRODUCT((AttendanceLog!$E$2:$E$5000=$A22)*(AttendanceLog!$C$2:$C$5000>=MAX($D22,Settings!$B$3))*((AttendanceLog!$I$2:$I$5000="")+(IFERROR(SEARCH(","&$C22&",",","&AttendanceLog!$I$2:$I$5000&","),0)>0)))) -> 0 | F22: =IF($A22="","",SUMPRODUCT((EventLog!$C$2:$C$5000>=MAX($D22,Settings!$B$3))*(EventLog!$C$2:$C$5000<=TODAY())*((EventLog!$F$2:$F$5000="")+(IFERROR(SEARCH(","&$C22&",",","&EventLog!$F$2:$F$5000&","),0)>0)))) -> 4 | G22: =IFERROR(E22/F22,0) -> 0 | H22: =IFERROR(__xludf.DUMMYFUNCTION("IFERROR(MAX(FILTER(AttendanceLog!$C:$C,AttendanceLog!$E:$E=$A22,(AttendanceLog!$I:$I="""")+(IFERROR(SEARCH("",""&$C22&"","","",""&AttendanceLog!$I:$I&"",""),0)>0))),"""")"),"")
A23: 2026B678 | B23: Active | C23: Dorm B | D23: 46235.333 | E23: =IF($A23="","",SUMPRODUCT((AttendanceLog!$E$2:$E$5000=$A23)*(AttendanceLog!$C$2:$C$5000>=MAX($D23,Settings!$B$3))*((AttendanceLog!$I$2:$I$5000="")+(IFERROR(SEARCH(","&$C23&",",","&AttendanceLog!$I$2:$I$5000&","),0)>0)))) -> 2 | F23: =IF($A23="","",SUMPRODUCT((EventLog!$C$2:$C$5000>=MAX($D23,Settings!$B$3))*(EventLog!$C$2:$C$5000<=TODAY())*((EventLog!$F$2:$F$5000="")+(IFERROR(SEARCH(","&$C23&",",","&EventLog!$F$2:$F$5000&","),0)>0)))) -> 4 | G23: =IFERROR(E23/F23,0) -> 0.5 | H23: =IFERROR(__xludf.DUMMYFUNCTION("IFERROR(MAX(FILTER(AttendanceLog!$C:$C,AttendanceLog!$E:$E=$A23,(AttendanceLog!$I:$I="""")+(IFERROR(SEARCH("",""&$C23&"","","",""&AttendanceLog!$I:$I&"",""),0)>0))),"""")"),46305.33333333333) -> 46305.333
A24: 2026B680 | B24: Active | C24: Dorm B | D24: 46242.333 | E24: =IF($A24="","",SUMPRODUCT((AttendanceLog!$E$2:$E$5000=$A24)*(AttendanceLog!$C$2:$C$5000>=MAX($D24,Settings!$B$3))*((AttendanceLog!$I$2:$I$5000="")+(IFERROR(SEARCH(","&$C24&",",","&AttendanceLog!$I$2:$I$5000&","),0)>0)))) -> 1 | F24: =IF($A24="","",SUMPRODUCT((EventLog!$C$2:$C$5000>=MAX($D24,Settings!$B$3))*(EventLog!$C$2:$C$5000<=TODAY())*((EventLog!$F$2:$F$5000="")+(IFERROR(SEARCH(","&$C24&",",","&EventLog!$F$2:$F$5000&","),0)>0)))) -> 4 | G24: =IFERROR(E24/F24,0) -> 0.25 | H24: =IFERROR(__xludf.DUMMYFUNCTION("IFERROR(MAX(FILTER(AttendanceLog!$C:$C,AttendanceLog!$E:$E=$A24,(AttendanceLog!$I:$I="""")+(IFERROR(SEARCH("",""&$C24&"","","",""&AttendanceLog!$I:$I&"",""),0)>0))),"""")"),46304.0) -> 46304
A25: 2026B686 | B25: Active | C25: Dorm B | D25: 46235.333 | E25: =IF($A25="","",SUMPRODUCT((AttendanceLog!$E$2:$E$5000=$A25)*(AttendanceLog!$C$2:$C$5000>=MAX($D25,Settings!$B$3))*((AttendanceLog!$I$2:$I$5000="")+(IFERROR(SEARCH(","&$C25&",",","&AttendanceLog!$I$2:$I$5000&","),0)>0)))) -> 4 | F25: =IF($A25="","",SUMPRODUCT((EventLog!$C$2:$C$5000>=MAX($D25,Settings!$B$3))*(EventLog!$C$2:$C$5000<=TODAY())*((EventLog!$F$2:$F$5000="")+(IFERROR(SEARCH(","&$C25&",",","&EventLog!$F$2:$F$5000&","),0)>0)))) -> 4 | G25: =IFERROR(E25/F25,0) -> 1 | H25: =IFERROR(__xludf.DUMMYFUNCTION("IFERROR(MAX(FILTER(AttendanceLog!$C:$C,AttendanceLog!$E:$E=$A25,(AttendanceLog!$I:$I="""")+(IFERROR(SEARCH("",""&$C25&"","","",""&AttendanceLog!$I:$I&"",""),0)>0))),"""")"),46306.0) -> 46306
A26: 2026B690 | B26: Active | C26: Dorm B | D26: 46235.333 | E26: =IF($A26="","",SUMPRODUCT((AttendanceLog!$E$2:$E$5000=$A26)*(AttendanceLog!$C$2:$C$5000>=MAX($D26,Settings!$B$3))*((AttendanceLog!$I$2:$I$5000="")+(IFERROR(SEARCH(","&$C26&",",","&AttendanceLog!$I$2:$I$5000&","),0)>0)))) -> 3 | F26: =IF($A26="","",SUMPRODUCT((EventLog!$C$2:$C$5000>=MAX($D26,Settings!$B$3))*(EventLog!$C$2:$C$5000<=TODAY())*((EventLog!$F$2:$F$5000="")+(IFERROR(SEARCH(","&$C26&",",","&EventLog!$F$2:$F$5000&","),0)>0)))) -> 4 | G26: =IFERROR(E26/F26,0) -> 0.75 | H26: =IFERROR(__xludf.DUMMYFUNCTION("IFERROR(MAX(FILTER(AttendanceLog!$C:$C,AttendanceLog!$E:$E=$A26,(AttendanceLog!$I:$I="""")+(IFERROR(SEARCH("",""&$C26&"","","",""&AttendanceLog!$I:$I&"",""),0)>0))),"""")"),46306.0) -> 46306
A27: 2026C621 | B27: Active | C27: Dorm B | D27: 46235.333 | E27: =IF($A27="","",SUMPRODUCT((AttendanceLog!$E$2:$E$5000=$A27)*(AttendanceLog!$C$2:$C$5000>=MAX($D27,Settings!$B$3))*((AttendanceLog!$I$2:$I$5000="")+(IFERROR(SEARCH(","&$C27&",",","&AttendanceLog!$I$2:$I$5000&","),0)>0)))) -> 3 | F27: =IF($A27="","",SUMPRODUCT((EventLog!$C$2:$C$5000>=MAX($D27,Settings!$B$3))*(EventLog!$C$2:$C$5000<=TODAY())*((EventLog!$F$2:$F$5000="")+(IFERROR(SEARCH(","&$C27&",",","&EventLog!$F$2:$F$5000&","),0)>0)))) -> 4 | G27: =IFERROR(E27/F27,0) -> 0.75 | H27: =IFERROR(__xludf.DUMMYFUNCTION("IFERROR(MAX(FILTER(AttendanceLog!$C:$C,AttendanceLog!$E:$E=$A27,(AttendanceLog!$I:$I="""")+(IFERROR(SEARCH("",""&$C27&"","","",""&AttendanceLog!$I:$I&"",""),0)>0))),"""")"),46305.33333333333) -> 46305.333
A28: 2026M027 | B28: Active | C28: Dorm B | D28: 46235.333 | E28: =IF($A28="","",SUMPRODUCT((AttendanceLog!$E$2:$E$5000=$A28)*(AttendanceLog!$C$2:$C$5000>=MAX($D28,Settings!$B$3))*((AttendanceLog!$I$2:$I$5000="")+(IFERROR(SEARCH(","&$C28&",",","&AttendanceLog!$I$2:$I$5000&","),0)>0)))) -> 0 | F28: =IF($A28="","",SUMPRODUCT((EventLog!$C$2:$C$5000>=MAX($D28,Settings!$B$3))*(EventLog!$C$2:$C$5000<=TODAY())*((EventLog!$F$2:$F$5000="")+(IFERROR(SEARCH(","&$C28&",",","&EventLog!$F$2:$F$5000&","),0)>0)))) -> 4 | G28: =IFERROR(E28/F28,0) -> 0 | H28: =IFERROR(__xludf.DUMMYFUNCTION("IFERROR(MAX(FILTER(AttendanceLog!$C:$C,AttendanceLog!$E:$E=$A28,(AttendanceLog!$I:$I="""")+(IFERROR(SEARCH("",""&$C28&"","","",""&AttendanceLog!$I:$I&"",""),0)>0))),"""")"),"")
A29: 2026M629 | B29: Active | C29: Dorm B | D29: 46235.333 | E29: =IF($A29="","",SUMPRODUCT((AttendanceLog!$E$2:$E$5000=$A29)*(AttendanceLog!$C$2:$C$5000>=MAX($D29,Settings!$B$3))*((AttendanceLog!$I$2:$I$5000="")+(IFERROR(SEARCH(","&$C29&",",","&AttendanceLog!$I$2:$I$5000&","),0)>0)))) -> 3 | F29: =IF($A29="","",SUMPRODUCT((EventLog!$C$2:$C$5000>=MAX($D29,Settings!$B$3))*(EventLog!$C$2:$C$5000<=TODAY())*((EventLog!$F$2:$F$5000="")+(IFERROR(SEARCH(","&$C29&",",","&EventLog!$F$2:$F$5000&","),0)>0)))) -> 4 | G29: =IFERROR(E29/F29,0) -> 0.75 | H29: =IFERROR(__xludf.DUMMYFUNCTION("IFERROR(MAX(FILTER(AttendanceLog!$C:$C,AttendanceLog!$E:$E=$A29,(AttendanceLog!$I:$I="""")+(IFERROR(SEARCH("",""&$C29&"","","",""&AttendanceLog!$I:$I&"",""),0)>0))),"""")"),46306.0) -> 46306
A30: 2026M643 | B30: Active | C30: Dorm B | D30: 46235.333 | E30: =IF($A30="","",SUMPRODUCT((AttendanceLog!$E$2:$E$5000=$A30)*(AttendanceLog!$C$2:$C$5000>=MAX($D30,Settings!$B$3))*((AttendanceLog!$I$2:$I$5000="")+(IFERROR(SEARCH(","&$C30&",",","&AttendanceLog!$I$2:$I$5000&","),0)>0)))) -> 2 | F30: =IF($A30="","",SUMPRODUCT((EventLog!$C$2:$C$5000>=MAX($D30,Settings!$B$3))*(EventLog!$C$2:$C$5000<=TODAY())*((EventLog!$F$2:$F$5000="")+(IFERROR(SEARCH(","&$C30&",",","&EventLog!$F$2:$F$5000&","),0)>0)))) -> 4 | G30: =IFERROR(E30/F30,0) -> 0.5 | H30: =IFERROR(__xludf.DUMMYFUNCTION("IFERROR(MAX(FILTER(AttendanceLog!$C:$C,AttendanceLog!$E:$E=$A30,(AttendanceLog!$I:$I="""")+(IFERROR(SEARCH("",""&$C30&"","","",""&AttendanceLog!$I:$I&"",""),0)>0))),"""")"),46305.33333333333) -> 46305.333
A31: 2026M649 | B31: Active | C31: Dorm B | D31: 46235.333 | E31: =IF($A31="","",SUMPRODUCT((AttendanceLog!$E$2:$E$5000=$A31)*(AttendanceLog!$C$2:$C$5000>=MAX($D31,Settings!$B$3))*((AttendanceLog!$I$2:$I$5000="")+(IFERROR(SEARCH(","&$C31&",",","&AttendanceLog!$I$2:$I$5000&","),0)>0)))) -> 2 | F31: =IF($A31="","",SUMPRODUCT((EventLog!$C$2:$C$5000>=MAX($D31,Settings!$B$3))*(EventLog!$C$2:$C$5000<=TODAY())*((EventLog!$F$2:$F$5000="")+(IFERROR(SEARCH(","&$C31&",",","&EventLog!$F$2:$F$5000&","),0)>0)))) -> 4 | G31: =IFERROR(E31/F31,0) -> 0.5 | H31: =IFERROR(__xludf.DUMMYFUNCTION("IFERROR(MAX(FILTER(AttendanceLog!$C:$C,AttendanceLog!$E:$E=$A31,(AttendanceLog!$I:$I="""")+(IFERROR(SEARCH("",""&$C31&"","","",""&AttendanceLog!$I:$I&"",""),0)>0))),"""")"),46305.33333333333) -> 46305.333
A32: 2026M659 | B32: Active | C32: Dorm B | D32: 46243.333 | E32: =IF($A32="","",SUMPRODUCT((AttendanceLog!$E$2:$E$5000=$A32)*(AttendanceLog!$C$2:$C$5000>=MAX($D32,Settings!$B$3))*((AttendanceLog!$I$2:$I$5000="")+(IFERROR(SEARCH(","&$C32&",",","&AttendanceLog!$I$2:$I$5000&","),0)>0)))) -> 3 | F32: =IF($A32="","",SUMPRODUCT((EventLog!$C$2:$C$5000>=MAX($D32,Settings!$B$3))*(EventLog!$C$2:$C$5000<=TODAY())*((EventLog!$F$2:$F$5000="")+(IFERROR(SEARCH(","&$C32&",",","&EventLog!$F$2:$F$5000&","),0)>0)))) -> 4 | G32: =IFERROR(E32/F32,0) -> 0.75 | H32: =IFERROR(__xludf.DUMMYFUNCTION("IFERROR(MAX(FILTER(AttendanceLog!$C:$C,AttendanceLog!$E:$E=$A32,(AttendanceLog!$I:$I="""")+(IFERROR(SEARCH("",""&$C32&"","","",""&AttendanceLog!$I:$I&"",""),0)>0))),"""")"),46306.0) -> 46306
A33: 2026M661 | B33: Active | C33: Dorm B | D33: 46235.333 | E33: =IF($A33="","",SUMPRODUCT((AttendanceLog!$E$2:$E$5000=$A33)*(AttendanceLog!$C$2:$C$5000>=MAX($D33,Settings!$B$3))*((AttendanceLog!$I$2:$I$5000="")+(IFERROR(SEARCH(","&$C33&",",","&AttendanceLog!$I$2:$I$5000&","),0)>0)))) -> 0 | F33: =IF($A33="","",SUMPRODUCT((EventLog!$C$2:$C$5000>=MAX($D33,Settings!$B$3))*(EventLog!$C$2:$C$5000<=TODAY())*((EventLog!$F$2:$F$5000="")+(IFERROR(SEARCH(","&$C33&",",","&EventLog!$F$2:$F$5000&","),0)>0)))) -> 4 | G33: =IFERROR(E33/F33,0) -> 0 | H33: =IFERROR(__xludf.DUMMYFUNCTION("IFERROR(MAX(FILTER(AttendanceLog!$C:$C,AttendanceLog!$E:$E=$A33,(AttendanceLog!$I:$I="""")+(IFERROR(SEARCH("",""&$C33&"","","",""&AttendanceLog!$I:$I&"",""),0)>0))),"""")"),"")
A34: 2026M666 | B34: Active | C34: Dorm B | D34: 46241.333 | E34: =IF($A34="","",SUMPRODUCT((AttendanceLog!$E$2:$E$5000=$A34)*(AttendanceLog!$C$2:$C$5000>=MAX($D34,Settings!$B$3))*((AttendanceLog!$I$2:$I$5000="")+(IFERROR(SEARCH(","&$C34&",",","&AttendanceLog!$I$2:$I$5000&","),0)>0)))) -> 4 | F34: =IF($A34="","",SUMPRODUCT((EventLog!$C$2:$C$5000>=MAX($D34,Settings!$B$3))*(EventLog!$C$2:$C$5000<=TODAY())*((EventLog!$F$2:$F$5000="")+(IFERROR(SEARCH(","&$C34&",",","&EventLog!$F$2:$F$5000&","),0)>0)))) -> 4 | G34: =IFERROR(E34/F34,0) -> 1 | H34: =IFERROR(__xludf.DUMMYFUNCTION("IFERROR(MAX(FILTER(AttendanceLog!$C:$C,AttendanceLog!$E:$E=$A34,(AttendanceLog!$I:$I="""")+(IFERROR(SEARCH("",""&$C34&"","","",""&AttendanceLog!$I:$I&"",""),0)>0))),"""")"),46306.0) -> 46306
A35: 2026M672 | B35: Active | C35: Dorm B | D35: 46237.333 | E35: =IF($A35="","",SUMPRODUCT((AttendanceLog!$E$2:$E$5000=$A35)*(AttendanceLog!$C$2:$C$5000>=MAX($D35,Settings!$B$3))*((AttendanceLog!$I$2:$I$5000="")+(IFERROR(SEARCH(","&$C35&",",","&AttendanceLog!$I$2:$I$5000&","),0)>0)))) -> 2 | F35: =IF($A35="","",SUMPRODUCT((EventLog!$C$2:$C$5000>=MAX($D35,Settings!$B$3))*(EventLog!$C$2:$C$5000<=TODAY())*((EventLog!$F$2:$F$5000="")+(IFERROR(SEARCH(","&$C35&",",","&EventLog!$F$2:$F$5000&","),0)>0)))) -> 4 | G35: =IFERROR(E35/F35,0) -> 0.5 | H35: =IFERROR(__xludf.DUMMYFUNCTION("IFERROR(MAX(FILTER(AttendanceLog!$C:$C,AttendanceLog!$E:$E=$A35,(AttendanceLog!$I:$I="""")+(IFERROR(SEARCH("",""&$C35&"","","",""&AttendanceLog!$I:$I&"",""),0)>0))),"""")"),46305.33333333333) -> 46305.333
A36: 2026M680 | B36: Active | C36: Dorm B | D36: 46249.333 | E36: =IF($A36="","",SUMPRODUCT((AttendanceLog!$E$2:$E$5000=$A36)*(AttendanceLog!$C$2:$C$5000>=MAX($D36,Settings!$B$3))*((AttendanceLog!$I$2:$I$5000="")+(IFERROR(SEARCH(","&$C36&",",","&AttendanceLog!$I$2:$I$5000&","),0)>0)))) -> 2 | F36: =IF($A36="","",SUMPRODUCT((EventLog!$C$2:$C$5000>=MAX($D36,Settings!$B$3))*(EventLog!$C$2:$C$5000<=TODAY())*((EventLog!$F$2:$F$5000="")+(IFERROR(SEARCH(","&$C36&",",","&EventLog!$F$2:$F$5000&","),0)>0)))) -> 4 | G36: =IFERROR(E36/F36,0) -> 0.5 | H36: =IFERROR(__xludf.DUMMYFUNCTION("IFERROR(MAX(FILTER(AttendanceLog!$C:$C,AttendanceLog!$E:$E=$A36,(AttendanceLog!$I:$I="""")+(IFERROR(SEARCH("",""&$C36&"","","",""&AttendanceLog!$I:$I&"",""),0)>0))),"""")"),46305.33333333333) -> 46305.333
A37: 2026M681 | B37: Active | C37: Dorm B | D37: 46235.333 | E37: =IF($A37="","",SUMPRODUCT((AttendanceLog!$E$2:$E$5000=$A37)*(AttendanceLog!$C$2:$C$5000>=MAX($D37,Settings!$B$3))*((AttendanceLog!$I$2:$I$5000="")+(IFERROR(SEARCH(","&$C37&",",","&AttendanceLog!$I$2:$I$5000&","),0)>0)))) -> 1 | F37: =IF($A37="","",SUMPRODUCT((EventLog!$C$2:$C$5000>=MAX($D37,Settings!$B$3))*(EventLog!$C$2:$C$5000<=TODAY())*((EventLog!$F$2:$F$5000="")+(IFERROR(SEARCH(","&$C37&",",","&EventLog!$F$2:$F$5000&","),0)>0)))) -> 4 | G37: =IFERROR(E37/F37,0) -> 0.25 | H37: =IFERROR(__xludf.DUMMYFUNCTION("IFERROR(MAX(FILTER(AttendanceLog!$C:$C,AttendanceLog!$E:$E=$A37,(AttendanceLog!$I:$I="""")+(IFERROR(SEARCH("",""&$C37&"","","",""&AttendanceLog!$I:$I&"",""),0)>0))),"""")"),46305.33333333333) -> 46305.333
